Workbook

Sheet 2026
F1: Year | H1: 2026 | I1: 2026 | J1: 2026 | K1: 2026 | L1: 2026 | M1: 2026 | N1: 2026 | O1: 2026 | P1: 2026 | Q1: 2026 | R1: 2026 | S1: 2026 | T1: 2026
F2: Month | H2: 1 | I2: =H2+1 -> 2 | J2: =I2+1 -> 3 | K2: =J2+1 -> 4 | L2: =K2+1 -> 5 | M2: =L2+1 -> 6 | N2: =M2+1 -> 7 | O2: =N2+1 -> 8 | P2: =O2+1 -> 9 | ... S2: =R2+1 -> 12
D4: Revenue | H4: ='2026-01'!H1024 -> 21834800 | I4: ='2026-01'!I1024+'2026-02'!H1024 -> 25030800 | J4: ='2026-03'!H1024+'2026-02'!I1024+'2026-01'!J1024 -> 27893600 | K4: ='2026-04'!H1024+'2026-03'!I1024+'2026-02'!J1024+'2026-01'!K1024 -> 39536380 | L4: ='2026-04'!I1024+'2026-03'!J1024+'2026-02'!K1024+'2026-01'!L1024+'2026-05'!H1024 -> 44275318 | M4: ='2026-04'!J1024+'2026-03'!K1024+'2026-02'!L1024+'2026-01'!M1024+'2026-05'!I1024+'2026-06'!H1024 -> 48131980 | N4: ='2026-04'!K1024+'2026-03'!L1024+'2026-02'!M1024+'2026-01'!N1024+'2026-05'!J1024+'2026-06'!I1024+'2026-07'!H1024 -> 65737928 | O4: ='2026-04'!L1024+'2026-03'!M1024+'2026-02'!N1024+'2026-01'!O1024+'2026-05'!K1024+'2026-06'!J1024+'2026-07'!I1024+'2026-08'!H1024 -> 70821411 | P4: ='2026-04'!M1024+'2026-03'!N1024+'2026-02'!O1024+'2026-01'!P1024+'2026-05'!L1024+'2026-06'!K1024+'2026-07'!J1024+'2026-08'!I1024+'2026-09'!H1024 -> 75848778 | Q4: ='2026-04'!N1024+'2026-03'!O1024+'2026-02'!P1024+'2026-01'!Q1024+'2026-05'!M1024+'2026-06'!L1024+'2026-07'!K1024+'2026-08'!J1024+'2026-09'!I1024+'2026-10'!H1024 -> 81006083 | R4: ='2026-04'!O1024+'2026-03'!P1024+'2026-02'!Q1024+'2026-01'!R1024+'2026-05'!N1024+'2026-06'!M1024+'2026-07'!L1024+'2026-08'!K1024+'2026-09'!J1024+'2026-10'!I1024+'2026-11'!H1024 -> 77477623 | S4: ='2026-04'!P1024+'2026-03'!Q1024+'2026-02'!R1024+'2026-01'!S1024+'2026-05'!O1024+'2026-06'!N1024+'2026-07'!M1024+'2026-08'!L1024+'2026-09'!K1024+'2026-10'!J1024+'2026-11'!I1024+'2026-12'!H1024 -> 72290816 | T4: =SUM(E4:S4) -> 6.4988552e+08
D6: Activation | H6: ='2026-01'!H1027 -> 21834800 | I6: ='2026-01'!I1027+'2026-02'!H1027 -> 21299300 | J6: ='2026-03'!H1027+'2026-02'!I1027+'2026-01'!J1027 -> 21834800 | K6: ='2026-04'!H1027+'2026-03'!I1027+'2026-02'!J1027+'2026-01'!K1027 -> 31583000 | L6: ='2026-04'!I1027+'2026-03'!J1027+'2026-02'!K1027+'2026-01'!L1027+'2026-05'!H1027 -> 33287500 | M6: ='2026-04'!J1027+'2026-03'!K1027+'2026-02'!L1027+'2026-01'!M1027+'2026-05'!I1027+'2026-06'!H1027 -> 33287500 | N6: ='2026-04'!K1027+'2026-03'!L1027+'2026-02'!M1027+'2026-01'!N1027+'2026-05'!J1027+'2026-06'!I1027+'2026-07'!H1027 -> 48876500 | O6: ='2026-04'!L1027+'2026-03'!M1027+'2026-02'!N1027+'2026-01'!O1027+'2026-05'!K1027+'2026-06'!J1027+'2026-07'!I1027+'2026-08'!H1027 -> 48876500 | P6: ='2026-04'!M1027+'2026-03'!N1027+'2026-02'!O1027+'2026-01'!P1027+'2026-05'!L1027+'2026-06'!K1027+'2026-07'!J1027+'2026-08'!I1027+'2026-09'!H1027 -> 48876500 | Q6: ='2026-04'!N1027+'2026-03'!O1027+'2026-02'!P1027+'2026-01'!Q1027+'2026-05'!M1027+'2026-06'!L1027+'2026-07'!K1027+'2026-08'!J1027+'2026-09'!I1027+'2026-10'!H1027 -> 51442900 | R6: ='2026-04'!O1027+'2026-03'!P1027+'2026-02'!Q1027+'2026-01'!R1027+'2026-05'!N1027+'2026-06'!M1027+'2026-07'!L1027+'2026-08'!K1027+'2026-09'!J1027+'2026-10'!I1027+'2026-11'!H1027 -> 45615900 | S6: ='2026-04'!P1027+'2026-03'!Q1027+'2026-02'!R1027+'2026-01'!S1027+'2026-05'!O1027+'2026-06'!N1027+'2026-07'!M1027+'2026-08'!L1027+'2026-09'!K1027+'2026-10'!J1027+'2026-11'!I1027+'2026-12'!H1027 -> 36725300 | T6: =SUM(E6:S6) -> 443540500
D8: Renewall | H8: ='2026-01'!H1064 -> 0 | I8: ='2026-01'!I1064+'2026-02'!H1064 -> 49500 | J8: ='2026-03'!H1064+'2026-02'!I1064+'2026-01'!J1064 -> 100800 | K8: ='2026-04'!H1064+'2026-03'!I1064+'2026-02'!J1064+'2026-01'!K1064 -> 238380 | L8: ='2026-04'!I1064+'2026-03'!J1064+'2026-02'!K1064+'2026-01'!L1064+'2026-05'!H1064 -> 363818 | M8: ='2026-04'!J1064+'2026-03'!K1064+'2026-02'!L1064+'2026-01'!M1064+'2026-05'!I1064+'2026-06'!H1064 -> 545479.8 | N8: ='2026-04'!K1064+'2026-03'!L1064+'2026-02'!M1064+'2026-01'!N1064+'2026-05'!J1064+'2026-06'!I1064+'2026-07'!H1064 -> 746427.78 | O8: ='2026-04'!L1064+'2026-03'!M1064+'2026-02'!N1064+'2026-01'!O1064+'2026-05'!K1064+'2026-06'!J1064+'2026-07'!I1064+'2026-08'!H1064 -> 1628910.6 | P8: ='2026-04'!M1064+'2026-03'!N1064+'2026-02'!O1064+'2026-01'!P1064+'2026-05'!L1064+'2026-06'!K1064+'2026-07'!J1064+'2026-08'!I1064+'2026-09'!H1064 -> 2010278 | Q8: ='2026-04'!N1064+'2026-03'!O1064+'2026-02'!P1064+'2026-01'!Q1064+'2026-05'!M1064+'2026-06'!L1064+'2026-07'!K1064+'2026-08'!J1064+'2026-09'!I1064+'2026-10'!H1064 -> 2662182.8 | R8: ='2026-04'!O1064+'2026-03'!P1064+'2026-02'!Q1064+'2026-01'!R1064+'2026-05'!N1064+'2026-06'!M1064+'2026-07'!L1064+'2026-08'!K1064+'2026-09'!J1064+'2026-10'!I1064+'2026-11'!H1064 -> 3241722.9 | S8: ='2026-04'!P1064+'2026-03'!Q1064+'2026-02'!R1064+'2026-01'!S1064+'2026-05'!O1064+'2026-06'!N1064+'2026-07'!M1064+'2026-08'!L1064+'2026-09'!K1064+'2026-10'!J1064+'2026-11'!I1064+'2026-12'!H1064 -> 3797516.3 | T8: =SUM(E8:S8) -> 15385016
D10: Expansion | H10: ='2026-01'!H1081 -> 0 | I10: ='2026-01'!I1081+'2026-02'!H1081 -> 3682000 | J10: ='2026-03'!H1081+'2026-02'!I1081+'2026-01'!J1081 -> 5958000 | K10: ='2026-04'!H1081+'2026-03'!I1081+'2026-02'!J1081+'2026-01'!K1081 -> 7715000 | L10: ='2026-04'!I1081+'2026-03'!J1081+'2026-02'!K1081+'2026-01'!L1081+'2026-05'!H1081 -> 10624000 | M10: ='2026-04'!J1081+'2026-03'!K1081+'2026-02'!L1081+'2026-01'!M1081+'2026-05'!I1081+'2026-06'!H1081 -> 14299000 | N10: ='2026-04'!K1081+'2026-03'!L1081+'2026-02'!M1081+'2026-01'!N1081+'2026-05'!J1081+'2026-06'!I1081+'2026-07'!H1081 -> 16115000 | O10: ='2026-04'!L1081+'2026-03'!M1081+'2026-02'!N1081+'2026-01'!O1081+'2026-05'!K1081+'2026-06'!J1081+'2026-07'!I1081+'2026-08'!H1081 -> 20316000 | P10: ='2026-04'!M1081+'2026-03'!N1081+'2026-02'!O1081+'2026-01'!P1081+'2026-05'!L1081+'2026-06'!K1081+'2026-07'!J1081+'2026-08'!I1081+'2026-09'!H1081 -> 24962000 | Q10: ='2026-04'!N1081+'2026-03'!O1081+'2026-02'!P1081+'2026-01'!Q1081+'2026-05'!M1081+'2026-06'!L1081+'2026-07'!K1081+'2026-08'!J1081+'2026-09'!I1081+'2026-10'!H1081 -> 26901000 | R10: ='2026-04'!O1081+'2026-03'!P1081+'2026-02'!Q1081+'2026-01'!R1081+'2026-05'!N1081+'2026-06'!M1081+'2026-07'!L1081+'2026-08'!K1081+'2026-09'!J1081+'2026-10'!I1081+'2026-11'!H1081 -> 28620000 | S10: ='2026-04'!P1081+'2026-03'!Q1081+'2026-02'!R1081+'2026-01'!S1081+'2026-05'!O1081+'2026-06'!N1081+'2026-07'!M1081+'2026-08'!L1081+'2026-09'!K1081+'2026-10'!J1081+'2026-11'!I1081+'2026-12'!H1081 -> 31768000 | T10: =SUM(E10:S10) -> 190960000
F12: Revenue | G12: Month/ Year | H12: 1/2026 | I12: 2/2026 | J12: 3/2026 | K12: 4/2026 | L12: 5/2026 | M12: 6/2026 | N12: 7/2026 | O12: 8/2026 | P12: 9/2026 | Q12: 10/2026 | R12: 11/2026 | S12: 12/2026
G13: 1/2026 | H13: ='2026-01'!H1024 -> 21834800 | I13: ='2026-01'!I1024 -> 3713500 | J13: ='2026-01'!J1024 -> 2420650 | K13: ='2026-01'!K1024 -> 1838115 | L13: ='2026-01'!L1024 -> 1266326.5 | M13: ='2026-01'!M1024 -> 2591719.1 | N13: ='2026-01'!N1024 -> 930651.06 | O13: ='2026-01'!O1024 -> 1397580.2 | ... S13: ='2026-01'!S1024 -> 1575794.1
G14: 2/2026 | I14: ='2026-02'!H1024 -> 21317300 | J14: ='2026-02'!I1024 -> 3606650 | K14: ='2026-02'!J1024 -> 2367115 | L14: ='2026-02'!K1024 -> 1824726.5 | M14: ='2026-02'!L1024 -> 1238119.1 | N14: ='2026-02'!M1024 -> 2474371.1 | O14: ='2026-02'!N1024 -> 931804.17 | P14: ='2026-02'!O1024 -> 1393278.6 | ... S14: ='2026-02'!R1024 -> 448402.89
G15: 3/2026 | J15: ='2026-03'!H1024 -> 21866300 | K15: ='2026-03'!I1024 -> 3716650 | L15: ='2026-03'!J1024 -> 2424115 | M15: ='2026-03'!K1024 -> 1841926.5 | N15: ='2026-03'!L1024 -> 1270519.1 | O15: ='2026-03'!M1024 -> 2596331.1 | P15: ='2026-03'!N1024 -> 935724.17 | Q15: ='2026-03'!O1024 -> 1403160.6 | ... S15: ='2026-03'!Q1024 -> 487585.35
G16: 4/2026 | K16: ='2026-04'!H1024 -> 31614500 | L16: ='2026-04'!I1024 -> 5436650 | M16: ='2026-04'!J1024 -> 3397115 | N16: ='2026-04'!K1024 -> 2740726.5 | O16: ='2026-04'!L1024 -> 1843719.1 | P16: ='2026-04'!M1024 -> 3550771.1 | Q16: ='2026-04'!N1024 -> 1363084.2 | R16: ='2026-04'!O1024 -> 1763654.6 | S16: ='2026-04'!P1024 -> 2752347
G17: 5/2026 | L17: ='2026-05'!H1024 -> 33323500 | M17: ='2026-05'!I1024 -> 5739600 | N17: ='2026-05'!J1024 -> 3669560 | O17: ='2026-05'!K1024 -> 2858316 | P17: ='2026-05'!L1024 -> 1907907.6 | Q17: ='2026-05'!M1024 -> 3803298.4 | R17: ='2026-05'!N1024 -> 1451936.2 | S17: ='2026-05'!O1024 -> 1877503.8
G18: 6/2026 | M18: ='2026-06'!H1024 -> 33323500 | N18: ='2026-06'!I1024 -> 5739600 | O18: ='2026-06'!J1024 -> 3669560 | P18: ='2026-06'!K1024 -> 2858316 | Q18: ='2026-06'!L1024 -> 1907907.6 | R18: ='2026-06'!M1024 -> 3803298.4 | S18: ='2026-06'!N1024 -> 1451936.2
G19: 7/2026 | N19: ='2026-07'!H1024 -> 48912500 | O19: ='2026-07'!I1024 -> 8611600 | P19: ='2026-07'!J1024 -> 5577560 | Q19: ='2026-07'!K1024 -> 4323516 | R19: ='2026-07'!L1024 -> 2892307.6 | S19: ='2026-07'!M1024 -> 5839858.4
G20: 8/2026 | O20: ='2026-08'!H1024 -> 48912500 | P20: ='2026-08'!I1024 -> 8611600 | Q20: ='2026-08'!J1024 -> 5577560 | R20: ='2026-08'!K1024 -> 4323516 | S20: ='2026-08'!L1024 -> 2892307.6
G21: 9/2026 | P21: ='2026-09'!H1024 -> 48912500 | Q21: ='2026-09'!I1024 -> 8611600 | R21: ='2026-09'!J1024 -> 5577560 | S21: ='2026-09'!K1024 -> 4323516
G22: 10/2026 | Q22: ='2026-10'!H1024 -> 51474400 | R22: ='2026-10'!I1024 -> 8998650 | S22: ='2026-10'!J1024 -> 5893115
G23: 11/2026 | R23: ='2026-11'!H1024 -> 45647400 | S23: ='2026-11'!I1024 -> 8000650
G24: 12/2026 | S24: ='2026-12'!H1024 -> 36747800
H25: =SUM(H13:H24) -> 21834800 | I25: =SUM(I13:I24) -> 25030800 | J25: =SUM(J13:J24) -> 27893600 | K25: =SUM(K13:K24) -> 39536380 | L25: =SUM(L13:L24) -> 44275318 | M25: =SUM(M13:M24) -> 48131980 | N25: =SUM(N13:N24) -> 65737928 | O25: =SUM(O13:O24) -> 70821411 | ... S25: =SUM(S13:S24) -> 72290816
H26: =H25=H4 -> TRUE | I26: =I25=I4 -> TRUE | J26: =J25=J4 -> TRUE | K26: =K25=K4 -> TRUE | L26: =L25=L4 -> TRUE | M26: =M25=M4 -> TRUE | N26: =N25=N4 -> TRUE | O26: =O25=O4 -> TRUE | ... S26: =S25=S4 -> TRUE
H28: 5 | I28: 6 | J28: 7 | K28: 8 | L28: 9 | M28: 10 | N28: 11 | O28: 12 | P28: 13 | Q28: 14 | R28: 15 | S28: 16
F29: Activation | G29: Month/ Year | H29: 1/2026 | I29: 2/2026 | J29: 3/2026 | K29: 4/2026 | L29: 5/2026 | M29: 6/2026 | N29: 7/2026 | O29: 8/2026 | P29: 9/2026 | Q29: 10/2026 | R29: 11/2026 | S29: 12/2026
F30: ="2026-01" -> 2026-01 | G30: 1/2026 | H30: =IFERROR(__xludf.DUMMYFUNCTION("QUERY( INDIRECT(""'"" &$F30 & ""'!D:Z""),""SELECT Col""&H$28&"" WHERE Col1 = 'Activation'"")"),2.18348E7) -> 21834800 | I30: =IFERROR(__xludf.DUMMYFUNCTION("QUERY( INDIRECT(""'"" &$F30 & ""'!D:Z""),""SELECT Col""&I$28&"" WHERE Col1 = 'Activation'"")"),0.0) -> 0 | J30: =IFERROR(__xludf.DUMMYFUNCTION("QUERY( INDIRECT(""'"" &$F30 & ""'!D:Z""),""SELECT Col""&J$28&"" WHERE Col1 = 'Activation'"")"),0.0) -> 0 | K30: =IFERROR(__xludf.DUMMYFUNCTION("QUERY( INDIRECT(""'"" &$F30 & ""'!D:Z""),""SELECT Col""&K$28&"" WHERE Col1 = 'Activation'"")"),0.0) -> 0 | L30: =IFERROR(__xludf.DUMMYFUNCTION("QUERY( INDIRECT(""'"" &$F30 & ""'!D:Z""),""SELECT Col""&L$28&"" WHERE Col1 = 'Activation'"")"),0.0) -> 0 | M30: =IFERROR(__xludf.DUMMYFUNCTION("QUERY( INDIRECT(""'"" &$F30 & ""'!D:Z""),""SELECT Col""&M$28&"" WHERE Col1 = 'Activation'"")"),0.0) -> 0 | N30: =IFERROR(__xludf.DUMMYFUNCTION("QUERY( INDIRECT(""'"" &$F30 & ""'!D:Z""),""SELECT Col""&N$28&"" WHERE Col1 = 'Activation'"")"),0.0) -> 0 | O30: =IFERROR(__xludf.DUMMYFUNCTION("QUERY( INDIRECT(""'"" &$F30 & ""'!D:Z""),""SELECT Col""&O$28&"" WHERE Col1 = 'Activation'"")"),0.0) -> 0 | P30: =IFERROR(__xludf.DUMMYFUNCTION("QUERY( INDIRECT(""'"" &$F30 & ""'!D:Z""),""SELECT Col""&P$28&"" WHERE Col1 = 'Activation'"")"),0.0) -> 0 | Q30: =IFERROR(__xludf.DUMMYFUNCTION("QUERY( INDIRECT(""'"" &$F30 & ""'!D:Z""),""SELECT Col""&Q$28&"" WHERE Col1 = 'Activation'"")"),0.0) -> 0 | R30: =IFERROR(__xludf.DUMMYFUNCTION("QUERY( INDIRECT(""'"" &$F30 & ""'!D:Z""),""SELECT Col""&R$28&"" WHERE Col1 = 'Activation'"")"),0.0) -> 0 | S30: =IFERROR(__xludf.DUMMYFUNCTION("QUERY( INDIRECT(""'"" &$F30 & ""'!D:Z""),""SELECT Col""&S$28&"" WHERE Col1 = 'Activation'"")"),0.0) -> 0
F31: ="2026-02" -> 2026-02 | G31: 2/2026 | I31: ='2026-02'!H1027 -> 21299300 | J31: ='2026-02'!I1027 -> 0 | K31: ='2026-02'!J1027 -> 0 | L31: ='2026-02'!K1027 -> 0 | M31: ='2026-02'!L1027 -> 0 | N31: ='2026-02'!M1027 -> 0 | O31: ='2026-02'!N1027 -> 0 | P31: ='2026-02'!O1027 -> 0 | ... S31: ='2026-02'!R1027 -> 0
F32: ="2026-03" -> 2026-03 | G32: 3/2026 | J32: ='2026-03'!H1027 -> 21834800 | K32: ='2026-03'!I1027 -> 0 | L32: ='2026-03'!J1027 -> 0 | M32: ='2026-03'!K1027 -> 0 | N32: ='2026-03'!L1027 -> 0 | O32: ='2026-03'!M1027 -> 0 | P32: ='2026-03'!N1027 -> 0 | Q32: ='2026-03'!O1027 -> 0 | ... S32: ='2026-03'!Q1027 -> 0
F33: ="2026-04" -> 2026-04 | G33: 4/2026 | K33: ='2026-04'!H1027 -> 31583000 | L33: ='2026-04'!I1027 -> 0 | M33: ='2026-04'!J1027 -> 0 | N33: ='2026-04'!K1027 -> 0 | O33: ='2026-04'!L1027 -> 0 | P33: ='2026-04'!M1027 -> 0 | Q33: ='2026-04'!N1027 -> 0 | R33: ='2026-04'!O1027 -> 0 | S33: ='2026-04'!P1027 -> 0
F34: ="2026-05" -> 2026-05 | G34: 5/2026 | L34: ='2026-05'!H1027 -> 33287500 | M34: ='2026-05'!I1027 -> 0 | N34: ='2026-05'!J1027 -> 0 | O34: ='2026-05'!K1027 -> 0 | P34: ='2026-05'!L1027 -> 0 | Q34: ='2026-05'!M1027 -> 0 | R34: ='2026-05'!N1027 -> 0 | S34: ='2026-05'!O1027 -> 0
F35: ="2026-06" -> 2026-06 | G35: 6/2026 | M35: ='2026-06'!H1027 -> 33287500 | N35: ='2026-06'!I1027 -> 0 | O35: ='2026-06'!J1027 -> 0 | P35: ='2026-06'!K1027 -> 0 | Q35: ='2026-06'!L1027 -> 0 | R35: ='2026-06'!M1027 -> 0 | S35: ='2026-06'!N1027 -> 0
G36: 7/2026 | N36: ='2026-07'!H1027 -> 48876500 | O36: ='2026-07'!I1027 -> 0 | P36: ='2026-07'!J1027 -> 0 | Q36: ='2026-07'!K1027 -> 0 | R36: ='2026-07'!L1027 -> 0 | S36: ='2026-07'!M1027 -> 0
G37: 8/2026 | O37: ='2026-08'!H1027 -> 48876500 | P37: ='2026-08'!I1027 -> 0 | Q37: ='2026-08'!J1027 -> 0 | R37: ='2026-08'!K1027 -> 0 | S37: ='2026-08'!L1027 -> 0
G38: 9/2026 | P38: ='2026-09'!H1027 -> 48876500 | Q38: ='2026-09'!I1027 -> 0 | R38: ='2026-09'!J1027 -> 0 | S38: ='2026-09'!K1027 -> 0
G39: 10/2026 | Q39: ='2026-10'!H1027 -> 51442900 | R39: ='2026-10'!I1027 -> 0 | S39: ='2026-10'!J1027 -> 0
G40: 11/2026 | R40: ='2026-11'!H1027 -> 45615900 | S40: ='2026-11'!I1027 -> 0
G41: 12/2026 | S41: ='2026-12'!H1027 -> 36725300
H42: =SUM(H30:H41) -> 21834800 | I42: =SUM(I30:I41) -> 21299300 | J42: =SUM(J30:J41) -> 21834800 | K42: =SUM(K30:K41) -> 31583000 | L42: =SUM(L30:L41) -> 33287500 | M42: =SUM(M30:M41) -> 33287500 | N42: =SUM(N30:N41) -> 48876500 | O42: =SUM(O30:O41) -> 48876500 | ... S42: =SUM(S30:S41) -> 36725300
H43: =H42=H6 -> TRUE | I43: =I42=I6 -> TRUE | J43: =J42=J6 -> TRUE | K43: =K42=K6 -> TRUE | L43: =L42=L6 -> TRUE | M43: =M42=M6 -> TRUE | N43: =N42=N6 -> TRUE | O43: =O42=O6 -> TRUE | ... S43: =S42=S6 -> TRUE
F45: Renewall | G45: Month/ Year | H45: 1/2026 | I45: 2/2026 | J45: 3/2026 | K45: 4/2026 | L45: 5/2026 | M45: 6/2026 | N45: 7/2026 | O45: 8/2026 | P45: 9/2026 | Q45: 10/2026 | R45: 11/2026 | S45: 12/2026
G46: 1/2026 | H46: ='2026-01'!H1064 -> 0 | I46: ='2026-01'!I1064 -> 31500 | J46: ='2026-01'!J1064 -> 34650 | K46: ='2026-01'!K1064 -> 134115 | L46: ='2026-01'!L1064 -> 112326.5 | M46: ='2026-01'!M1064 -> 175719.15 | N46: ='2026-01'!N1064 -> 140651.07 | O46: ='2026-01'!O1064 -> 819580.17 | ... S46: ='2026-01'!S1064 -> 252794.09
G47: 2/2026 | I47: ='2026-02'!H1064 -> 18000 | J47: ='2026-02'!I1064 -> 34650 | K47: ='2026-02'!J1064 -> 38115 | L47: ='2026-02'!K1064 -> 142726.5 | M47: ='2026-02'!L1064 -> 118119.15 | N47: ='2026-02'!M1064 -> 179371.07 | O47: ='2026-02'!N1064 -> 151804.17 | P47: ='2026-02'!O1064 -> 815278.59 | ... S47: ='2026-02'!R1064 -> 448402.89
...

Sheet 2026-01
F1: Year | H1: 2026 | I1: 2026 | J1: 2026 | K1: 2026 | L1: 2026 | M1: 2026 | N1: 2026 | O1: 2026 | P1: 2026 | Q1: 2026 | R1: 2026 | S1: 2026 | T1: 2026
F2: Month | H2: 1 | I2: =H2+1 -> 2 | J2: =I2+1 -> 3 | K2: =J2+1 -> 4 | L2: =K2+1 -> 5 | M2: =L2+1 -> 6 | N2: =M2+1 -> 7 | O2: =N2+1 -> 8 | P2: =O2+1 -> 9 | ... S2: =R2+1 -> 12
B7: Awareness
D8: $ Media Budget | H8: ='Marketing - 2026'!H6 -> 4838976
D9: $ Cost per Lead (CPL) | H9: ='Marketing - 2026'!H9 -> 350
C10: VM1 | D10: # Leads | H10: =H8/H9 -> 13825.646
E11: # Non-ICP | H11: =H10-H13 -> 2767.6457
C12: CR1 | D12: % Lead → MQL | H12: 0.8
D13: # MQLs | H13: =SUM(H19:H23) -> 11058
E14: % Enterprise | H14: 0.046
E15: % Large | H15: 0.0511
E16: % Medium | H16: 0.2023
E17: % Small | H17: 0.476
E18: % Tiny | H18: 0.2246
E19: # Enterprise | H19: =ROUNDDOWN(($H$10*$H$12)*H14,0) -> 508
E20: # Large | H20: =ROUNDDOWN(($H$10*$H$12)*H15,0) -> 565
E21: # Medium | H21: =ROUNDDOWN(($H$10*$H$12)*H16,0) -> 2237
E22: # Small | H22: =ROUNDDOWN(($H$10*$H$12)*H17,0) -> 5264
E23: # Tiny | H23: =ROUNDDOWN(($H$10*$H$12)*H18,0) -> 2484
D24: $ Cost per MQL (CPMQL) | H24: =H8/H13 -> 437.59957
B27: Education
C29: VM2 | E29: # MQLs | H29: =H13 -> 11058
C30: CR2 | E30: % MQL → SQL | H30: =IFERROR(H31/H29,"-") -> 0.29272925
E31: # SQLs | H31: =SUM(H36,H41,H46,H51,H56) -> 3237
D33: Enterprise
C34: VM2 | E34: # MQLs | H34: =H19 -> 508
C35: CR2 | E35: % MQL → SQL | H35: 0.2
E36: # SQLs | H36: =ROUNDDOWN(H34*H35,0) -> 101
D38: Large
E39: # MQLs | H39: =H20 -> 565
C40: VM2 | E40: % MQL → SQL | H40: 0.25
E41: # SQLs | H41: =ROUNDDOWN(H39*H40,0) -> 141
D43: Medium
C44: VM2 | E44: # MQLs | H44: =H21 -> 2237
C45: CR2 | E45: % MQL → SQL | H45: 0.3
E46: # SQLs | H46: =ROUNDDOWN(H44*H45,0) -> 671
D48: Small
C49: VM2 | E49: =E34 -> # MQLs | H49: =H22 -> 5264
C50: CR2 | E50: % MQL → SQL | H50: 0.3
E51: # SQLs | H51: =ROUNDDOWN(H49*H50,0) -> 1579
...

Sheet 2026-02
F1: Year | H1: 2026 | I1: 2026 | J1: 2026 | K1: 2026 | L1: 2026 | M1: 2026 | N1: 2026 | O1: 2026 | P1: 2026 | Q1: 2026 | R1: 2026 | S1: 2026
F2: Month | H2: 2 | I2: =H2+1 -> 3 | J2: =I2+1 -> 4 | K2: =J2+1 -> 5 | L2: =K2+1 -> 6 | M2: =L2+1 -> 7 | N2: =M2+1 -> 8 | O2: =N2+1 -> 9 | P2: =O2+1 -> 10 | ... R2: =Q2+1 -> 12
B7: Awareness
D8: $ Media Budget | H8: ='Marketing - 2026'!I6 -> 4838976
D9: $ Cost per Lead (CPL) | H9: ='Marketing - 2026'!I9 -> 358.75
C10: VM1 | D10: # Leads | H10: =H8/H9 -> 13488.435
E11: # Non-ICP | H11: =H10-H13 -> 2700.4348
C12: CR1 | D12: % Lead → MQL | H12: 0.8
D13: # MQLs | H13: =SUM(H19:H23) -> 10788
E14: % Enterprise | H14: 0.046
E15: % Large | H15: 0.0511
E16: % Medium | H16: 0.2023
E17: % Small | H17: 0.476
E18: % Tiny | H18: 0.2246
E19: # Enterprise | H19: =ROUNDDOWN(($H$10*$H$12)*H14,0) -> 496
E20: # Large | H20: =ROUNDDOWN(($H$10*$H$12)*H15,0) -> 551
E21: # Medium | H21: =ROUNDDOWN(($H$10*$H$12)*H16,0) -> 2182
E22: # Small | H22: =ROUNDDOWN(($H$10*$H$12)*H17,0) -> 5136
E23: # Tiny | H23: =ROUNDDOWN(($H$10*$H$12)*H18,0) -> 2423
D24: $ Cost per MQL (CPMQL) | H24: =H8/H13 -> 448.55172
B27: Education
C29: VM2 | E29: # MQLs | H29: =H13 -> 10788
C30: CR2 | E30: % MQL → SQL | H30: =IFERROR(H31/H29,"-") -> 0.29254727
E31: # SQLs | H31: =SUM(H36,H41,H46,H51,H56) -> 3156
D33: Enterprise
C34: VM2 | E34: # MQLs | H34: =H19 -> 496
C35: CR2 | E35: % MQL → SQL | H35: 0.2
E36: # SQLs | H36: =ROUNDDOWN(H34*H35,0) -> 99
D38: Large
E39: # MQLs | H39: =H20 -> 551
C40: VM2 | E40: % MQL → SQL | H40: 0.25
E41: # SQLs | H41: =ROUNDDOWN(H39*H40,0) -> 137
D43: Medium
C44: VM2 | E44: # MQLs | H44: =H21 -> 2182
C45: CR2 | E45: % MQL → SQL | H45: 0.3
E46: # SQLs | H46: =ROUNDDOWN(H44*H45,0) -> 654
D48: Small
C49: VM2 | E49: =E34 -> # MQLs | H49: =H22 -> 5136
C50: CR2 | E50: % MQL → SQL | H50: 0.3
E51: # SQLs | H51: =ROUNDDOWN(H49*H50,0) -> 1540
...

Sheet 2026-03
F1: Year | H1: 2026 | I1: 2026 | J1: 2026 | K1: 2026 | L1: 2026 | M1: 2026 | N1: 2026 | O1: 2026 | P1: 2026 | Q1: 2026 | R1: 2026
F2: Month | H2: 3 | I2: =H2+1 -> 4 | J2: =I2+1 -> 5 | K2: =J2+1 -> 6 | L2: =K2+1 -> 7 | M2: =L2+1 -> 8 | N2: =M2+1 -> 9 | O2: =N2+1 -> 10 | P2: =O2+1 -> 11 | Q2: =P2+1 -> 12
B7: Awareness
D8: $ Media Budget | H8: ='Marketing - 2026'!J6 -> 5080924.8
D9: $ Cost per Lead (CPL) | H9: ='Marketing - 2026'!J9 -> 367.71875
C10: VM1 | D10: # Leads | H10: =H8/H9 -> 13817.421
E11: # Non-ICP | H11: =H10-H13 -> 2766.4211
C12: CR1 | D12: % Lead → MQL | H12: 0.8
D13: # MQLs | H13: =SUM(H19:H23) -> 11051
E14: % Enterprise | H14: 0.046
E15: % Large | H15: 0.0511
E16: % Medium | H16: 0.2023
E17: % Small | H17: 0.476
E18: % Tiny | H18: 0.2246
E19: # Enterprise | H19: =ROUNDDOWN(($H$10*$H$12)*H14,0) -> 508
E20: # Large | H20: =ROUNDDOWN(($H$10*$H$12)*H15,0) -> 564
E21: # Medium | H21: =ROUNDDOWN(($H$10*$H$12)*H16,0) -> 2236
E22: # Small | H22: =ROUNDDOWN(($H$10*$H$12)*H17,0) -> 5261
E23: # Tiny | H23: =ROUNDDOWN(($H$10*$H$12)*H18,0) -> 2482
D24: $ Cost per MQL (CPMQL) | H24: =H8/H13 -> 459.77059
B27: Education
C29: VM2 | E29: # MQLs | H29: =H13 -> 11051
C30: CR2 | E30: % MQL → SQL | H30: =IFERROR(H31/H29,"-") -> 0.2926432
E31: # SQLs | H31: =SUM(H36,H41,H46,H51,H56) -> 3234
D33: Enterprise
C34: VM2 | E34: # MQLs | H34: =H19 -> 508
C35: CR2 | E35: % MQL → SQL | H35: 0.2
E36: # SQLs | H36: =ROUNDDOWN(H34*H35,0) -> 101
D38: Large
E39: # MQLs | H39: =H20 -> 564
C40: VM2 | E40: % MQL → SQL | H40: 0.25
E41: # SQLs | H41: =ROUNDDOWN(H39*H40,0) -> 141
D43: Medium
C44: VM2 | E44: # MQLs | H44: =H21 -> 2236
C45: CR2 | E45: % MQL → SQL | H45: 0.3
E46: # SQLs | H46: =ROUNDDOWN(H44*H45,0) -> 670
D48: Small
C49: VM2 | E49: =E34 -> # MQLs | H49: =H22 -> 5261
C50: CR2 | E50: % MQL → SQL | H50: 0.3
E51: # SQLs | H51: =ROUNDDOWN(H49*H50,0) -> 1578
...

Sheet 2026-04
F1: Year | H1: 2026 | I1: 2026 | J1: 2026 | K1: 2026 | L1: 2026 | M1: 2026 | N1: 2026 | O1: 2026 | P1: 2026 | Q1: 2026
F2: Month | H2: 4 | I2: =H2+1 -> 5 | J2: =I2+1 -> 6 | K2: =J2+1 -> 7 | L2: =K2+1 -> 8 | M2: =L2+1 -> 9 | N2: =M2+1 -> 10 | O2: =N2+1 -> 11 | P2: =O2+1 -> 12
B7: Awareness
D8: $ Media Budget | H8: ='Marketing - 2026'!K6 -> 5589017.3
D9: $ Cost per Lead (CPL) | H9: ='Marketing - 2026'!K9 -> 386.10469
C10: VM1 | D10: # Leads | H10: =H8/H9 -> 14475.393
E11: # Non-ICP | H11: =H10-H13 -> 2898.3935
C12: CR1 | D12: % Lead → MQL | H12: 0.8
D13: # MQLs | H13: =SUM(H19:H23) -> 11577
E14: % Enterprise | H14: 0.046
E15: % Large | H15: 0.0511
E16: % Medium | H16: 0.2023
E17: % Small | H17: 0.476
E18: % Tiny | H18: 0.2246
E19: # Enterprise | H19: =ROUNDDOWN(($H$10*$H$12)*H14,0) -> 532
E20: # Large | H20: =ROUNDDOWN(($H$10*$H$12)*H15,0) -> 591
E21: # Medium | H21: =ROUNDDOWN(($H$10*$H$12)*H16,0) -> 2342
E22: # Small | H22: =ROUNDDOWN(($H$10*$H$12)*H17,0) -> 5512
E23: # Tiny | H23: =ROUNDDOWN(($H$10*$H$12)*H18,0) -> 2600
D24: $ Cost per MQL (CPMQL) | H24: =H8/H13 -> 482.76905
B27: Education
C29: VM2 | E29: # MQLs | H29: =H13 -> 11577
C30: CR2 | E30: % MQL → SQL | H30: =IFERROR(H31/H29,"-") -> 0.29264922
E31: # SQLs | H31: =SUM(H36,H41,H46,H51,H56) -> 3388
D33: Enterprise
C34: VM2 | E34: # MQLs | H34: =H19 -> 532
C35: CR2 | E35: % MQL → SQL | H35: 0.2
E36: # SQLs | H36: =ROUNDDOWN(H34*H35,0) -> 106
D38: Large
E39: # MQLs | H39: =H20 -> 591
C40: VM2 | E40: % MQL → SQL | H40: 0.25
E41: # SQLs | H41: =ROUNDDOWN(H39*H40,0) -> 147
D43: Medium
C44: VM2 | E44: # MQLs | H44: =H21 -> 2342
C45: CR2 | E45: % MQL → SQL | H45: 0.3
E46: # SQLs | H46: =ROUNDDOWN(H44*H45,0) -> 702
D48: Small
C49: VM2 | E49: =E34 -> # MQLs | H49: =H22 -> 5512
C50: CR2 | E50: % MQL → SQL | H50: 0.3
E51: # SQLs | H51: =ROUNDDOWN(H49*H50,0) -> 1653
...

Sheet 2026-05
F1: Year | H1: 2026 | I1: 2026 | J1: 2026 | K1: 2026 | L1: 2026 | M1: 2026 | N1: 2026 | O1: 2026 | P1: 2026
F2: Month | H2: 5 | I2: =H2+1 -> 6 | J2: =I2+1 -> 7 | K2: =J2+1 -> 8 | L2: =K2+1 -> 9 | M2: =L2+1 -> 10 | N2: =M2+1 -> 11 | O2: =N2+1 -> 12
B7: Awareness
D8: $ Media Budget | H8: ='Marketing - 2026'!L6 -> 6147919
D9: $ Cost per Lead (CPL) | H9: ='Marketing - 2026'!L9 -> 405.40992
C10: VM1 | D10: # Leads | H10: =H8/H9 -> 15164.698
E11: # Non-ICP | H11: =H10-H13 -> 3035.6979
C12: CR1 | D12: % Lead → MQL | H12: 0.8
D13: # MQLs | H13: =SUM(H19:H23) -> 12129
E14: % Enterprise | H14: 0.046
E15: % Large | H15: 0.0511
E16: % Medium | H16: 0.2023
E17: % Small | H17: 0.476
E18: % Tiny | H18: 0.2246
E19: # Enterprise | H19: =ROUNDDOWN(($H$10*$H$12)*H14,0) -> 558
E20: # Large | H20: =ROUNDDOWN(($H$10*$H$12)*H15,0) -> 619
E21: # Medium | H21: =ROUNDDOWN(($H$10*$H$12)*H16,0) -> 2454
E22: # Small | H22: =ROUNDDOWN(($H$10*$H$12)*H17,0) -> 5774
E23: # Tiny | H23: =ROUNDDOWN(($H$10*$H$12)*H18,0) -> 2724
D24: $ Cost per MQL (CPMQL) | H24: =H8/H13 -> 506.87765
B27: Education
C29: VM2 | E29: # MQLs | H29: =H13 -> 12129
C30: CR2 | E30: % MQL → SQL | H30: =IFERROR(H31/H29,"-") -> 0.29268695
E31: # SQLs | H31: =SUM(H36,H41,H46,H51,H56) -> 3550
D33: Enterprise
C34: VM2 | E34: # MQLs | H34: =H19 -> 558
C35: CR2 | E35: % MQL → SQL | H35: 0.2
E36: # SQLs | H36: =ROUNDDOWN(H34*H35,0) -> 111
D38: Large
E39: # MQLs | H39: =H20 -> 619
C40: VM2 | E40: % MQL → SQL | H40: 0.25
E41: # SQLs | H41: =ROUNDDOWN(H39*H40,0) -> 154
D43: Medium
C44: VM2 | E44: # MQLs | H44: =H21 -> 2454
C45: CR2 | E45: % MQL → SQL | H45: 0.3
E46: # SQLs | H46: =ROUNDDOWN(H44*H45,0) -> 736
D48: Small
C49: VM2 | E49: =E34 -> # MQLs | H49: =H22 -> 5774
C50: CR2 | E50: % MQL → SQL | H50: 0.3
E51: # SQLs | H51: =ROUNDDOWN(H49*H50,0) -> 1732
...

Sheet 2026-06
F1: Year | H1: 2026 | I1: 2026 | J1: 2026 | K1: 2026 | L1: 2026 | M1: 2026 | N1: 2026 | O1: 2026
F2: Month | H2: 6 | I2: =H2+1 -> 7 | J2: =I2+1 -> 8 | K2: =J2+1 -> 9 | L2: =K2+1 -> 10 | M2: =L2+1 -> 11 | N2: =M2+1 -> 12
B7: Awareness
D8: $ Media Budget | H8: ='Marketing - 2026'!M6 -> 6455315
D9: $ Cost per Lead (CPL) | H9: ='Marketing - 2026'!M9 -> 425.68042
C10: VM1 | D10: # Leads | H10: =H8/H9 -> 15164.698
E11: # Non-ICP | H11: =H10-H13 -> 3035.6979
C12: CR1 | D12: % Lead → MQL | H12: 0.8
D13: # MQLs | H13: =SUM(H19:H23) -> 12129
E14: % Enterprise | H14: 0.046
E15: % Large | H15: 0.0511
E16: % Medium | H16: 0.2023
E17: % Small | H17: 0.476
E18: % Tiny | H18: 0.2246
E19: # Enterprise | H19: =ROUNDDOWN(($H$10*$H$12)*H14,0) -> 558
E20: # Large | H20: =ROUNDDOWN(($H$10*$H$12)*H15,0) -> 619
E21: # Medium | H21: =ROUNDDOWN(($H$10*$H$12)*H16,0) -> 2454
E22: # Small | H22: =ROUNDDOWN(($H$10*$H$12)*H17,0) -> 5774
E23: # Tiny | H23: =ROUNDDOWN(($H$10*$H$12)*H18,0) -> 2724
D24: $ Cost per MQL (CPMQL) | H24: =H8/H13 -> 532.22153
B27: Education
C29: VM2 | E29: # MQLs | H29: =H13 -> 12129
C30: CR2 | E30: % MQL → SQL | H30: =IFERROR(H31/H29,"-") -> 0.29268695
E31: # SQLs | H31: =SUM(H36,H41,H46,H51,H56) -> 3550
D33: Enterprise
C34: VM2 | E34: # MQLs | H34: =H19 -> 558
C35: CR2 | E35: % MQL → SQL | H35: 0.2
E36: # SQLs | H36: =ROUNDDOWN(H34*H35,0) -> 111
D38: Large
E39: # MQLs | H39: =H20 -> 619
C40: VM2 | E40: % MQL → SQL | H40: 0.25
E41: # SQLs | H41: =ROUNDDOWN(H39*H40,0) -> 154
D43: Medium
C44: VM2 | E44: # MQLs | H44: =H21 -> 2454
C45: CR2 | E45: % MQL → SQL | H45: 0.3
E46: # SQLs | H46: =ROUNDDOWN(H44*H45,0) -> 736
D48: Small
C49: VM2 | E49: =E34 -> # MQLs | H49: =H22 -> 5774
C50: CR2 | E50: % MQL → SQL | H50: 0.3
E51: # SQLs | H51: =ROUNDDOWN(H49*H50,0) -> 1732
...

Sheet 2026-07
F1: Year | H1: 2026 | I1: 2026 | J1: 2026 | K1: 2026 | L1: 2026 | M1: 2026 | N1: 2026
F2: Month | H2: 7 | I2: =H2+1 -> 8 | J2: =I2+1 -> 9 | K2: =J2+1 -> 10 | L2: =K2+1 -> 11 | M2: =L2+1 -> 12
B7: Awareness
D8: $ Media Budget | H8: ='Marketing - 2026'!N6 -> 6778080.7
D9: $ Cost per Lead (CPL) | H9: ='Marketing - 2026'!N9 -> 436.32243
C10: VM1 | D10: # Leads | H10: =H8/H9 -> 15534.569
E11: # Non-ICP | H11: =H10-H13 -> 3108.5686
C12: CR1 | D12: % Lead → MQL | H12: 0.8
D13: # MQLs | H13: =SUM(H19:H23) -> 12426
E14: % Enterprise | H14: 0.046
E15: % Large | H15: 0.0511
E16: % Medium | H16: 0.2023
E17: % Small | H17: 0.476
E18: % Tiny | H18: 0.2246
E19: # Enterprise | H19: =ROUNDDOWN(($H$10*$H$12)*H14,0) -> 571
E20: # Large | H20: =ROUNDDOWN(($H$10*$H$12)*H15,0) -> 635
E21: # Medium | H21: =ROUNDDOWN(($H$10*$H$12)*H16,0) -> 2514
E22: # Small | H22: =ROUNDDOWN(($H$10*$H$12)*H17,0) -> 5915
E23: # Tiny | H23: =ROUNDDOWN(($H$10*$H$12)*H18,0) -> 2791
D24: $ Cost per MQL (CPMQL) | H24: =H8/H13 -> 545.47567
B27: Education
C29: VM2 | E29: # MQLs | H29: =H13 -> 12426
C30: CR2 | E30: % MQL → SQL | H30: =IFERROR(H31/H29,"-") -> 0.29269274
E31: # SQLs | H31: =SUM(H36,H41,H46,H51,H56) -> 3637
D33: Enterprise
C34: VM2 | E34: # MQLs | H34: =H19 -> 571
C35: CR2 | E35: % MQL → SQL | H35: 0.2
E36: # SQLs | H36: =ROUNDDOWN(H34*H35,0) -> 114
D38: Large
E39: # MQLs | H39: =H20 -> 635
C40: VM2 | E40: % MQL → SQL | H40: 0.25
E41: # SQLs | H41: =ROUNDDOWN(H39*H40,0) -> 158
D43: Medium
C44: VM2 | E44: # MQLs | H44: =H21 -> 2514
C45: CR2 | E45: % MQL → SQL | H45: 0.3
E46: # SQLs | H46: =ROUNDDOWN(H44*H45,0) -> 754
D48: Small
C49: VM2 | E49: =E34 -> # MQLs | H49: =H22 -> 5915
C50: CR2 | E50: % MQL → SQL | H50: 0.3
E51: # SQLs | H51: =ROUNDDOWN(H49*H50,0) -> 1774
...

Sheet 2026-08
F1: Year | H1: 2026 | I1: 2026 | J1: 2026 | K1: 2026 | L1: 2026 | M1: 2026
F2: Month | H2: 8 | I2: =H2+1 -> 9 | J2: =I2+1 -> 10 | K2: =J2+1 -> 11 | L2: =K2+1 -> 12
B7: Awareness
D8: $ Media Budget | H8: ='Marketing - 2026'!O6 -> 6778080.7
D9: $ Cost per Lead (CPL) | H9: ='Marketing - 2026'!O9 -> 436.32243
C10: VM1 | D10: # Leads | H10: =H8/H9 -> 15534.569
E11: # Non-ICP | H11: =H10-H13 -> 3108.5686
C12: CR1 | D12: % Lead → MQL | H12: 0.8
D13: # MQLs | H13: =SUM(H19:H23) -> 12426
E14: % Enterprise | H14: 0.046
E15: % Large | H15: 0.0511
E16: % Medium | H16: 0.2023
E17: % Small | H17: 0.476
E18: % Tiny | H18: 0.2246
E19: # Enterprise | H19: =ROUNDDOWN(($H$10*$H$12)*H14,0) -> 571
E20: # Large | H20: =ROUNDDOWN(($H$10*$H$12)*H15,0) -> 635
E21: # Medium | H21: =ROUNDDOWN(($H$10*$H$12)*H16,0) -> 2514
E22: # Small | H22: =ROUNDDOWN(($H$10*$H$12)*H17,0) -> 5915
E23: # Tiny | H23: =ROUNDDOWN(($H$10*$H$12)*H18,0) -> 2791
D24: $ Cost per MQL (CPMQL) | H24: =H8/H13 -> 545.47567
B27: Education
C29: VM2 | E29: # MQLs | H29: =H13 -> 12426
C30: CR2 | E30: % MQL → SQL | H30: =IFERROR(H31/H29,"-") -> 0.29269274
E31: # SQLs | H31: =SUM(H36,H41,H46,H51,H56) -> 3637
D33: Enterprise
C34: VM2 | E34: # MQLs | H34: =H19 -> 571
C35: CR2 | E35: % MQL → SQL | H35: 0.2
E36: # SQLs | H36: =ROUNDDOWN(H34*H35,0) -> 114
D38: Large
E39: # MQLs | H39: =H20 -> 635
C40: VM2 | E40: % MQL → SQL | H40: 0.25
E41: # SQLs | H41: =ROUNDDOWN(H39*H40,0) -> 158
D43: Medium
C44: VM2 | E44: # MQLs | H44: =H21 -> 2514
C45: CR2 | E45: % MQL → SQL | H45: 0.3
E46: # SQLs | H46: =ROUNDDOWN(H44*H45,0) -> 754
D48: Small
C49: VM2 | E49: =E34 -> # MQLs | H49: =H22 -> 5915
C50: CR2 | E50: % MQL → SQL | H50: 0.3
E51: # SQLs | H51: =ROUNDDOWN(H49*H50,0) -> 1774
...

Sheet 2026-09
F1: Year | H1: 2026 | I1: 2026 | J1: 2026 | K1: 2026 | L1: 2026
F2: Month | H2: 9 | I2: =H2+1 -> 10 | J2: =I2+1 -> 11 | K2: =J2+1 -> 12
B7: Awareness
D8: $ Media Budget | H8: ='Marketing - 2026'!P6 -> 6778080.7
D9: $ Cost per Lead (CPL) | H9: ='Marketing - 2026'!P9 -> 436.32243
C10: VM1 | D10: # Leads | H10: =H8/H9 -> 15534.569
E11: # Non-ICP | H11: =H10-H13 -> 3108.5686
C12: CR1 | D12: % Lead → MQL | H12: 0.8
D13: # MQLs | H13: =SUM(H19:H23) -> 12426
E14: % Enterprise | H14: 0.046
E15: % Large | H15: 0.0511
E16: % Medium | H16: 0.2023
E17: % Small | H17: 0.476
E18: % Tiny | H18: 0.2246
E19: # Enterprise | H19: =ROUNDDOWN(($H$10*$H$12)*H14,0) -> 571
E20: # Large | H20: =ROUNDDOWN(($H$10*$H$12)*H15,0) -> 635
E21: # Medium | H21: =ROUNDDOWN(($H$10*$H$12)*H16,0) -> 2514
E22: # Small | H22: =ROUNDDOWN(($H$10*$H$12)*H17,0) -> 5915
E23: # Tiny | H23: =ROUNDDOWN(($H$10*$H$12)*H18,0) -> 2791
D24: $ Cost per MQL (CPMQL) | H24: =H8/H13 -> 545.47567
B27: Education
C29: VM2 | E29: # MQLs | H29: =H13 -> 12426
C30: CR2 | E30: % MQL → SQL | H30: =IFERROR(H31/H29,"-") -> 0.29269274
E31: # SQLs | H31: =SUM(H36,H41,H46,H51,H56) -> 3637
D33: Enterprise
C34: VM2 | E34: # MQLs | H34: =H19 -> 571
C35: CR2 | E35: % MQL → SQL | H35: 0.2
E36: # SQLs | H36: =ROUNDDOWN(H34*H35,0) -> 114
D38: Large
E39: # MQLs | H39: =H20 -> 635
C40: VM2 | E40: % MQL → SQL | H40: 0.25
E41: # SQLs | H41: =ROUNDDOWN(H39*H40,0) -> 158
D43: Medium
C44: VM2 | E44: # MQLs | H44: =H21 -> 2514
C45: CR2 | E45: % MQL → SQL | H45: 0.3
E46: # SQLs | H46: =ROUNDDOWN(H44*H45,0) -> 754
D48: Small
C49: VM2 | E49: =E34 -> # MQLs | H49: =H22 -> 5915
C50: CR2 | E50: % MQL → SQL | H50: 0.3
E51: # SQLs | H51: =ROUNDDOWN(H49*H50,0) -> 1774
...

Sheet 2026-10
F1: Year | H1: 2026 | I1: 2026 | J1: 2026 | K1: 2026
F2: Month | H2: 10 | I2: =H2+1 -> 11 | J2: =I2+1 -> 12
B7: Awareness
D8: $ Media Budget | H8: ='Marketing - 2026'!Q6 -> 6778080.7
D9: $ Cost per Lead (CPL) | H9: ='Marketing - 2026'!Q9 -> 458.13855
C10: VM1 | D10: # Leads | H10: =H8/H9 -> 14794.827
E11: # Non-ICP | H11: =H10-H13 -> 2961.8273
C12: CR1 | D12: % Lead → MQL | H12: 0.8
D13: # MQLs | H13: =SUM(H19:H23) -> 11833
E14: % Enterprise | H14: 0.046
E15: % Large | H15: 0.0511
E16: % Medium | H16: 0.2023
E17: % Small | H17: 0.476
E18: % Tiny | H18: 0.2246
E19: # Enterprise | H19: =ROUNDDOWN(($H$10*$H$12)*H14,0) -> 544
E20: # Large | H20: =ROUNDDOWN(($H$10*$H$12)*H15,0) -> 604
E21: # Medium | H21: =ROUNDDOWN(($H$10*$H$12)*H16,0) -> 2394
E22: # Small | H22: =ROUNDDOWN(($H$10*$H$12)*H17,0) -> 5633
E23: # Tiny | H23: =ROUNDDOWN(($H$10*$H$12)*H18,0) -> 2658
D24: $ Cost per MQL (CPMQL) | H24: =H8/H13 -> 572.81169
B27: Education
C29: VM2 | E29: # MQLs | H29: =H13 -> 11833
C30: CR2 | E30: % MQL → SQL | H30: =IFERROR(H31/H29,"-") -> 0.29265613
E31: # SQLs | H31: =SUM(H36,H41,H46,H51,H56) -> 3463
D33: Enterprise
C34: VM2 | E34: # MQLs | H34: =H19 -> 544
C35: CR2 | E35: % MQL → SQL | H35: 0.2
E36: # SQLs | H36: =ROUNDDOWN(H34*H35,0) -> 108
D38: Large
E39: # MQLs | H39: =H20 -> 604
C40: VM2 | E40: % MQL → SQL | H40: 0.25
E41: # SQLs | H41: =ROUNDDOWN(H39*H40,0) -> 151
D43: Medium
C44: VM2 | E44: # MQLs | H44: =H21 -> 2394
C45: CR2 | E45: % MQL → SQL | H45: 0.3
E46: # SQLs | H46: =ROUNDDOWN(H44*H45,0) -> 718
D48: Small
C49: VM2 | E49: =E34 -> # MQLs | H49: =H22 -> 5633
C50: CR2 | E50: % MQL → SQL | H50: 0.3
E51: # SQLs | H51: =ROUNDDOWN(H49*H50,0) -> 1689
...

Sheet 2026-11
F1: Year | H1: 2026 | I1: 2026 | J1: 2026
F2: Month | H2: 11 | I2: =H2+1 -> 12
B7: Awareness
D8: $ Media Budget | H8: ='Marketing - 2026'!R6 -> 5422464.6
D9: $ Cost per Lead (CPL) | H9: ='Marketing - 2026'!R9 -> 412.32469
C10: VM1 | D10: # Leads | H10: =H8/H9 -> 13150.958
E11: # Non-ICP | H11: =H10-H13 -> 2633.9576
C12: CR1 | D12: % Lead → MQL | H12: 0.8
D13: # MQLs | H13: =SUM(H19:H23) -> 10517
E14: % Enterprise | H14: 0.046
E15: % Large | H15: 0.0511
E16: % Medium | H16: 0.2023
E17: % Small | H17: 0.476
E18: % Tiny | H18: 0.2246
E19: # Enterprise | H19: =ROUNDDOWN(($H$10*$H$12)*H14,0) -> 483
E20: # Large | H20: =ROUNDDOWN(($H$10*$H$12)*H15,0) -> 537
E21: # Medium | H21: =ROUNDDOWN(($H$10*$H$12)*H16,0) -> 2128
E22: # Small | H22: =ROUNDDOWN(($H$10*$H$12)*H17,0) -> 5007
E23: # Tiny | H23: =ROUNDDOWN(($H$10*$H$12)*H18,0) -> 2362
D24: $ Cost per MQL (CPMQL) | H24: =H8/H13 -> 515.59043
B27: Education
C29: VM2 | E29: # MQLs | H29: =H13 -> 10517
C30: CR2 | E30: % MQL → SQL | H30: =IFERROR(H31/H29,"-") -> 0.29266901
E31: # SQLs | H31: =SUM(H36,H41,H46,H51,H56) -> 3078
D33: Enterprise
C34: VM2 | E34: # MQLs | H34: =H19 -> 483
C35: CR2 | E35: % MQL → SQL | H35: 0.2
E36: # SQLs | H36: =ROUNDDOWN(H34*H35,0) -> 96
D38: Large
E39: # MQLs | H39: =H20 -> 537
C40: VM2 | E40: % MQL → SQL | H40: 0.25
E41: # SQLs | H41: =ROUNDDOWN(H39*H40,0) -> 134
D43: Medium
C44: VM2 | E44: # MQLs | H44: =H21 -> 2128
C45: CR2 | E45: % MQL → SQL | H45: 0.3
E46: # SQLs | H46: =ROUNDDOWN(H44*H45,0) -> 638
D48: Small
C49: VM2 | E49: =E34 -> # MQLs | H49: =H22 -> 5007
C50: CR2 | E50: % MQL → SQL | H50: 0.3
E51: # SQLs | H51: =ROUNDDOWN(H49*H50,0) -> 1502
...

Sheet 2026-12
F1: Year | H1: 2026 | I1: 2026
F2: Month | H2: 12
B7: Awareness
D8: $ Media Budget | H8: ='Marketing - 2026'!S6 -> 4337971.7
D9: $ Cost per Lead (CPL) | H9: ='Marketing - 2026'!S9 -> 412.32469
C10: VM1 | D10: # Leads | H10: =H8/H9 -> 10520.766
E11: # Non-ICP | H11: =H10-H13 -> 2105.7661
C12: CR1 | D12: % Lead → MQL | H12: 0.8
D13: # MQLs | H13: =SUM(H19:H23) -> 8415
E14: % Enterprise | H14: 0.046
E15: % Large | H15: 0.0511
E16: % Medium | H16: 0.2023
E17: % Small | H17: 0.476
E18: % Tiny | H18: 0.2246
E19: # Enterprise | H19: =ROUNDDOWN(($H$10*$H$12)*H14,0) -> 387
E20: # Large | H20: =ROUNDDOWN(($H$10*$H$12)*H15,0) -> 430
E21: # Medium | H21: =ROUNDDOWN(($H$10*$H$12)*H16,0) -> 1702
E22: # Small | H22: =ROUNDDOWN(($H$10*$H$12)*H17,0) -> 4006
E23: # Tiny | H23: =ROUNDDOWN(($H$10*$H$12)*H18,0) -> 1890
D24: $ Cost per MQL (CPMQL) | H24: =H8/H13 -> 515.50465
B27: Education
C29: VM2 | E29: # MQLs | H29: =H13 -> 8415
C30: CR2 | E30: % MQL → SQL | H30: =IFERROR(H31/H29,"-") -> 0.29257279
E31: # SQLs | H31: =SUM(H36,H41,H46,H51,H56) -> 2462
D33: Enterprise
C34: VM2 | E34: # MQLs | H34: =H19 -> 387
C35: CR2 | E35: % MQL → SQL | H35: 0.2
E36: # SQLs | H36: =ROUNDDOWN(H34*H35,0) -> 77
D38: Large
E39: # MQLs | H39: =H20 -> 430
C40: VM2 | E40: % MQL → SQL | H40: 0.25
E41: # SQLs | H41: =ROUNDDOWN(H39*H40,0) -> 107
D43: Medium
C44: VM2 | E44: # MQLs | H44: =H21 -> 1702
C45: CR2 | E45: % MQL → SQL | H45: 0.3
E46: # SQLs | H46: =ROUNDDOWN(H44*H45,0) -> 510
D48: Small
C49: VM2 | E49: =E34 -> # MQLs | H49: =H22 -> 4006
C50: CR2 | E50: % MQL → SQL | H50: 0.3
E51: # SQLs | H51: =ROUNDDOWN(H49*H50,0) -> 1201
...

Sheet Marketing - 2026
F1: Year | H1: 2026 | I1: 2026 | J1: 2026 | K1: 2026 | L1: 2026 | M1: 2026 | N1: 2026 | O1: 2026 | P1: 2026 | Q1: 2026 | R1: 2026 | S1: 2026 | T1: 2026
F2: Month | H2: 1 | I2: =H2+1 -> 2 | J2: =I2+1 -> 3 | K2: =J2+1 -> 4 | L2: =K2+1 -> 5 | M2: =L2+1 -> 6 | N2: =M2+1 -> 7 | O2: =N2+1 -> 8 | P2: =O2+1 -> 9 | ... S2: =R2+1 -> 12
B5: Awareness | U5: =3*100 -> 300
D6: $ Media Budget | H6: =4032480*1.2 -> 4838976 | I6: =H6*100% -> 4838976 | J6: =I6*105% -> 5080924.8 | K6: =J6*110% -> 5589017.3 | L6: =K6*110% -> 6147919 | M6: =L6*105% -> 6455315 | N6: =M6*105% -> 6778080.7 | O6: =N6*100% -> 6778080.7 | P6: =O6*100% -> 6778080.7 | Q6: =P6*100% -> 6778080.7 | R6: =Q6*80% -> 5422464.6 | S6: =R6*80% -> 4337971.7 | T6: =SUM(G6:S6) -> 69823887
E7: % Facebook | H7: 0.6 | I7: 0.6 | J7: 0.6 | K7: 0.6 | L7: 0.6 | M7: 0.6 | N7: 0.6 | O7: 0.6 | P7: 0.6 | Q7: 0.6 | R7: 0.6 | S7: 0.6
E8: $ Tax Media | H8: =H6*H7*12% -> 348406.27 | I8: =I6*I7*12% -> 348406.27 | J8: =J6*J7*12% -> 365826.59 | K8: =K6*K7*12% -> 402409.24 | L8: =L6*L7*12% -> 442650.17 | M8: =M6*M7*12% -> 464782.68 | N8: =N6*N7*12% -> 488021.81 | O8: =O6*O7*12% -> 488021.81 | ... S8: =S6*S7*12% -> 312333.96 | T8: =SUM(H8:S8) -> 5027319.9
D9: $ Cost per Lead (CPL) | H9: 350 | I9: =H9*102.5% -> 358.75 | J9: =I9*102.5% -> 367.71875 | K9: =J9*105% -> 386.10469 | L9: =K9*105% -> 405.40992 | M9: =L9*105% -> 425.68042 | N9: =M9*102.5% -> 436.32243 | O9: =N9*100% -> 436.32243 | P9: =O9*100% -> 436.32243 | Q9: =P9*105% -> 458.13855 | R9: =Q9*90% -> 412.32469 | S9: =R9*100% -> 412.32469
C10: VM1 | E10: # Leads | H10: =H6/H9 -> 13825.646 | I10: =I6/I9 -> 13488.435 | J10: =J6/J9 -> 13817.421 | K10: =K6/K9 -> 14475.393 | L10: =L6/L9 -> 15164.698 | M10: =M6/M9 -> 15164.698 | N10: =N6/N9 -> 15534.569 | O10: =O6/O9 -> 15534.569 | ... S10: =S6/S9 -> 10520.766 | T10: =SUM(H10:S10) -> 171006.55
C11: CR1 | D11: % Lead → MQL | H11: 0.8 | I11: 0.8 | J11: 0.8 | K11: 0.8 | L11: 0.8 | M11: 0.8 | N11: 0.8 | O11: 0.8 | P11: 0.8 | Q11: 0.8 | R11: 0.8 | S11: 0.8 | T11: =DIVIDE(T6,T12) -> 510.37495
E12: # MQLs | H12: =ROUNDUP(H10*H11,0) -> 11061 | I12: =ROUNDUP(I10*I11,0) -> 10791 | J12: =ROUNDUP(J10*J11,0) -> 11054 | K12: =ROUNDUP(K10*K11,0) -> 11581 | L12: =ROUNDUP(L10*L11,0) -> 12132 | M12: =ROUNDUP(M10*M11,0) -> 12132 | N12: =ROUNDUP(N10*N11,0) -> 12428 | O12: =ROUNDUP(O10*O11,0) -> 12428 | ... S12: =ROUNDUP(S10*S11,0) -> 8417 | T12: =SUM(H12:S12) -> 136809
E13: % Enterprise | H13: 0.046 | I13: 0.046 | J13: 0.046 | K13: 0.046 | L13: 0.046 | M13: 0.046 | N13: 0.046 | O13: 0.046 | P13: 0.046 | Q13: 0.046 | R13: 0.046 | S13: 0.046
E14: % Large | H14: 0.0511 | I14: 0.0511 | J14: 0.0511 | K14: 0.0511 | L14: 0.0511 | M14: 0.0511 | N14: 0.0511 | O14: 0.0511 | P14: 0.0511 | Q14: 0.0511 | R14: 0.0511 | S14: 0.0511
E15: % Medium | H15: 0.2023 | I15: 0.2023 | J15: 0.2023 | K15: 0.2023 | L15: 0.2023 | M15: 0.2023 | N15: 0.2023 | O15: 0.2023 | P15: 0.2023 | Q15: 0.2023 | R15: 0.2023 | S15: 0.2023
E16: % Small | H16: 0.476 | I16: 0.476 | J16: 0.476 | K16: 0.476 | L16: 0.476 | M16: 0.476 | N16: 0.476 | O16: 0.476 | P16: 0.476 | Q16: 0.476 | R16: 0.476 | S16: 0.476
E17: % Tiny | H17: 0.2246 | I17: 0.2246 | J17: 0.2246 | K17: 0.2246 | L17: 0.2246 | M17: 0.2246 | N17: 0.2246 | O17: 0.2246 | P17: 0.2246 | Q17: 0.2246 | R17: 0.2246 | S17: 0.2246
E18: # Enterprise | H18: =H$12*H13 -> 508.806 | I18: =I$12*I13 -> 496.386 | J18: =J$12*J13 -> 508.484 | K18: =K$12*K13 -> 532.726 | L18: =L$12*L13 -> 558.072 | M18: =M$12*M13 -> 558.072 | N18: =N$12*N13 -> 571.688 | O18: =O$12*O13 -> 571.688 | ... S18: =S$12*S13 -> 387.182
E19: # Large | H19: =H$12*H14 -> 565.2171 | I19: =I$12*I14 -> 551.4201 | J19: =J$12*J14 -> 564.8594 | K19: =K$12*K14 -> 591.7891 | L19: =L$12*L14 -> 619.9452 | M19: =M$12*M14 -> 619.9452 | N19: =N$12*N14 -> 635.0708 | O19: =O$12*O14 -> 635.0708 | ... S19: =S$12*S14 -> 430.1087
E20: # Medium | H20: =H$12*H15 -> 2237.6403 | I20: =I$12*I15 -> 2183.0193 | J20: =J$12*J15 -> 2236.2242 | K20: =K$12*K15 -> 2342.8363 | L20: =L$12*L15 -> 2454.3036 | M20: =M$12*M15 -> 2454.3036 | N20: =N$12*N15 -> 2514.1844 | O20: =O$12*O15 -> 2514.1844 | ... S20: =S$12*S15 -> 1702.7591
E21: # Small | H21: =H$12*H16 -> 5265.036 | I21: =I$12*I16 -> 5136.516 | J21: =J$12*J16 -> 5261.704 | K21: =K$12*K16 -> 5512.556 | L21: =L$12*L16 -> 5774.832 | M21: =M$12*M16 -> 5774.832 | N21: =N$12*N16 -> 5915.728 | O21: =O$12*O16 -> 5915.728 | ... S21: =S$12*S16 -> 4006.492
E22: # Tiny | H22: =H$12*H17 -> 2484.3006 | I22: =I$12*I17 -> 2423.6586 | J22: =J$12*J17 -> 2482.7284 | K22: =K$12*K17 -> 2601.0926 | L22: =L$12*L17 -> 2724.8472 | M22: =M$12*M17 -> 2724.8472 | N22: =N$12*N17 -> 2791.3288 | O22: =O$12*O17 -> 2791.3288 | ... S22: =S$12*S17 -> 1890.4582
D23: $ Cost per MQL (CPMQL) | H23: =(H6+H8)/H12 -> 468.9795 | I23: =(I6+I8)/I12 -> 480.71377 | J23: =(J6+J8)/J12 -> 492.74031 | K23: =(K6+K8)/K12 -> 517.34967 | L23: =(L6+L8)/L12 -> 543.23847 | M23: =(M6+M8)/M12 -> 570.4004 | N23: =(N6+N8)/N12 -> 584.65582 | O23: =(O6+O8)/O12 -> 584.65582 | ... S23: =(S6+S8)/S12 -> 552.48968

Sheet Pricing
I2: Average Ticket
I4: Enterprise
J6: Q1 | K6: Q2 | L6: Q3 | M6: Q4
I7: $ [Saber] | J7: 30000 | K7: 50000 | L7: 100000 | M7: 150000
I8: $ [Ter] | J8: 31600 | K8: 31600 | L8: 31600 | M8: 31600
I9: $ [Executar-no loyalty] | J9: 0 | K9: 0 | L9: 0 | M9: 0
I10: $ [Executar-loyalty] | J10: =14500*10 -> 145000 | K10: =14500*10 -> 145000 | L10: =14500*10 -> 145000 | M10: =14500*10 -> 145000
I11: $ [Potencializar] | J11: 0 | K11: 0 | L11: 0 | M11: 0
I14: Large
J16: Q1 | K16: Q2 | L16: Q3 | M16: Q4
I17: $ [Saber] | J17: 25000 | K17: 40000 | L17: 80000 | M17: 120000
I18: $ [Ter] | J18: 18000 | K18: 18000 | L18: 18000 | M18: 18000
I19: $ [Executar-no loyalty] | J19: 0 | K19: 0 | L19: 0 | M19: 0
I20: $ [Executar-loyalty] | J20: =11000*9 -> 99000 | K20: =11000*9 -> 99000 | L20: =11000*9 -> 99000 | M20: =11000*9 -> 99000
I21: $ [Potencializar] | J21: 0 | K21: 0 | L21: 0 | M21: 0
I24: Medium
J26: Q1 | K26: Q2 | L26: Q3 | M26: Q4
I27: $ [Saber] | J27: 20000 | K27: 40000 | L27: 80000 | M27: 100000
I28: $ [Ter] | J28: 15000 | K28: 15000 | L28: 15000 | M28: 15000
I29: $ [Executar-no loyalty] | J29: 0 | K29: 0 | L29: 0 | M29: 0
I30: $ [Executar-loyalty] | J30: =7000*7 -> 49000 | K30: =7000*7 -> 49000 | L30: =7000*7 -> 49000 | M30: =7000*7 -> 49000
I31: $ [Potencializar] | J31: 0 | K31: 0 | L31: 0 | M31: 0
I34: Small
J36: Q1 | K36: Q2 | L36: Q3 | M36: Q4
I37: $ [Saber] | J37: 20000 | K37: 30000 | L37: 40000 | M37: 40000
I38: $ [Ter] | J38: 11500 | K38: 11500 | L38: 11500 | M38: 11500
I39: $ [Executar-no loyalty] | J39: 0 | K39: 0 | L39: 0 | M39: 0
I40: $ [Executar-loyalty] | J40: 0 | K40: 0 | L40: 0 | M40: 0
I41: $ [Potencializar] | J41: 0 | K41: 0 | L41: 0 | M41: 0
I44: Tiny
J46: Q1 | K46: Q2 | L46: Q3 | M46: Q4
I47: $ [Saber] | J47: 15000 | K47: 20000 | L47: 30000 | M47: 30000
I48: $ [Ter] | J48: 7500 | K48: 7500 | L48: 7500 | M48: 7500
I49: $ [Executar-no loyalty] | J49: 0 | K49: 0 | L49: 0 | M49: 0
I50: $ [Executar-loyalty] | J50: 0 | K50: 0 | L50: 0 | M50: 0
I51: $ [Potencializar] | J51: 0 | K51: 0 | L51: 0 | M51: 0
